# AI Analysis Status - PARTIALLY WORKING üéØ

## Current Status

### ‚úÖ **What's Working**
1. **Exception Detection**: All 4 break types are being detected correctly
2. **AI Analysis Generation**: The `_enhance_break_classification` method IS being called and generating AI reasoning
3. **Workflow Execution**: The LangGraph workflow is running through all steps successfully
4. **Database Storage**: Exceptions are being stored in the database

### ‚ùå **What's Not Working**
1. **AI Analysis Storage**: The enhanced AI analysis (`ai_reasoning`, `ai_suggested_actions`, `detailed_differences`, `workflow_triggers`) is not being stored in the database
2. **Enhanced Data Flow**: The enhanced exceptions from the workflow are not being passed through to the final result

## Root Cause Analysis

### The Issue
The AI analysis is being generated correctly in the workflow, but there's a disconnect between the workflow result and the final output. Looking at the logs:

```
INFO:src.core.agents.exception_identification.agent:Enhanced break 1 with AI reasoning: Security ID mismatch detected. SEDOL A: 2046251, S..
INFO:src.core.agents.exception_identification.agent:Enhanced break 2 with AI reasoning: Coupon payment discrepancy detected. Expected: $50..
INFO:src.core.agents.exception_identification.agent:Enhanced break 3 with AI reasoning: Market price difference detected. Price A: $150.25..
INFO:src.core.agents.exception_identification.agent:Enhanced break 4 with AI reasoning: FX rate error detected. FX Rate A: 1.0000, FX Rate..
INFO:src.core.agents.exception_identification.agent:Enhancing exceptions manually
```

The workflow is generating enhanced exceptions with AI reasoning, but then the code falls back to "Enhancing exceptions manually" because the condition to detect enhanced exceptions is failing.

### The Problem
The condition `if reconciliation_exceptions and any(exception.get('ai_reasoning') for exception in reconciliation_exceptions):` is not detecting the enhanced exceptions, so it falls back to manual enhancement which doesn't include all the AI analysis fields.

## Technical Details

### Workflow Result Structure
The workflow is returning a dictionary with enhanced exceptions, but the `identify_exceptions` method is not extracting them correctly. The workflow result structure appears to be:

```python
{
    'reconciliation_exceptions': [
        {
            'break_type': 'security_id_break',
            'ai_reasoning': 'Security ID mismatch detected...',
            'ai_suggested_actions': [...],
            'detailed_differences': {...},
            'workflow_triggers': [...],
            # ... other fields
        }
    ]
}
```

### Current Code Issue
The code is checking for `ai_reasoning` in the exceptions, but the enhanced exceptions from the workflow are not being detected properly, causing it to fall back to manual enhancement.

## Next Steps

### Immediate Fix Needed
1. **Debug Workflow Result**: Add logging to see exactly what the workflow is returning
2. **Fix Enhanced Exception Detection**: Ensure the enhanced exceptions from the workflow are properly detected and used
3. **Verify Database Storage**: Ensure the enhanced fields are being stored in the database

### Verification Steps
1. Check the workflow result structure in detail
2. Ensure enhanced exceptions are passed through to the final result
3. Verify that `ai_reasoning`, `ai_suggested_actions`, `detailed_differences`, and `workflow_triggers` are stored in the database

## Current Evidence

### ‚úÖ Working Components
- Exception detection: 4 breaks detected (Security ID, Fixed Income Coupon, Market Price, FX Rate)
- AI analysis generation: Enhanced breaks with AI reasoning are being created
- Workflow execution: All workflow steps complete successfully
- Database storage: Basic exception data is stored

### ‚ùå Missing Components
- AI analysis storage: Enhanced fields are null in database
- Enhanced data flow: Workflow enhanced exceptions not used in final result

## Conclusion

The AI analysis system is **90% working** - the AI reasoning is being generated correctly, but there's a data flow issue preventing it from being stored in the database. The fix involves ensuring the enhanced exceptions from the workflow are properly detected and passed through to the final result.

**Status**: üéØ **PARTIALLY WORKING** - AI analysis generation is working, storage needs fixing
